<?xml version="1.0" ?>
<!-- Generated using onshape-to-robot -->
<!-- Onshape document_id: 3023829f8e4e5c564f6b4985 -->
<robot xmlns:xacro="http://www.ros.org/wiki/xacro">


   <!-- Link base footprint -->
  <link name="base_footprint"/>
  <!-- Joint base footprint -->
  <joint name="base_joint" type="fixed">
      <parent link="base_footprint" />
      <child link="base_link" />
      <origin xyz="0 0 0.0158450026" rpy="0 0 0" />
  </joint>

  <!-- Link base_link -->
  <link name="base_link">
    <inertial>
      <origin xyz="0.025787 -0.000348468 0.0673611" rpy="0 0 0"/>
      <mass value="16.1488"/>
      <inertia ixx="0.0959047" ixy="-0.000829231" ixz="-0.0172466" iyy="0.109975" iyz="0.000180341" izz="0.120294"/>
    </inertial>
    <!-- Part base_link -->
    <visual>
      <origin xyz="0 0 0" rpy="0 -0 0"/>
      <geometry>
        <mesh filename="package://my_robot_description/assets/base_link.stl"/>
      </geometry>
      <material name="base_link_material">
        <color rgba="0.0470588 0.470588 0.435294 1"/>
      </material>
    </visual>
    <collision>
      <origin xyz="0 0 0" rpy="0 -0 0"/>
      <geometry>
        <mesh filename="package://my_robot_description/assets/base_link.stl"/>
      </geometry>
    </collision>
  </link>
  <!-- Link llanta_dere_del -->
  <link name="llanta_dere_del_link">
    <inertial>
      <origin xyz="-0 -0 -0.0264625" rpy="0 0 0"/>
      <mass value="0.324568"/>
      <inertia ixx="0.00010149" ixy="0" ixz="0" iyy="0.000102087" iyz="0" izz="0.000172547"/>
    </inertial>
    <!-- Part llanta_dere_del -->
    <visual>
      <origin xyz="0 0 -0.015" rpy="1.5708 -0 0"/>
      <geometry>
        <mesh filename="package://my_robot_description/assets/llanta_dere_del.stl"/>
      </geometry>
      <material name="llanta_dere_del_material">
        <color rgba="0.980392 0.713725 0.00392157 1"/>
      </material>
    </visual>
    <collision>
      <origin xyz="0 0 -0.015" rpy="1.5708 -0 0"/>
      <geometry>
        <mesh filename="package://my_robot_description/assets/llanta_dere_del.stl"/>
      </geometry>
    </collision>
  </link>
  <!-- Joint from base_link to llanta_dere_del -->
  <joint name="llanta_dere_del_joint" type="continuous">
    <origin xyz="0.0441 -0.095 0.0162" rpy="-1.5708 -0 0"/>
    <parent link="base_link"/>
    <child link="llanta_dere_del_link"/>
    <axis xyz="0 0 1"/>
    <limit effort="100" velocity="100"/>
  </joint>
  <!-- Link llanta_dere_tra -->
  <link name="llanta_dere_tra_link">
    <inertial>
      <origin xyz="0 -0 -0.0264625" rpy="0 0 0"/>
      <mass value="0.324568"/>
      <inertia ixx="0.00010149" ixy="0" ixz="0" iyy="0.000102087" iyz="0" izz="0.000172547"/>
    </inertial>
    <!-- Part llanta_dere_tra -->
    <visual>
      <origin xyz="0 0 -0.015" rpy="1.5708 -0 0"/>
      <geometry>
        <mesh filename="package://my_robot_description/assets/llanta_dere_tra.stl"/>
      </geometry>
      <material name="llanta_dere_tra_material">
        <color rgba="0.980392 0.713725 0.00392157 1"/>
      </material>
    </visual>
    <collision>
      <origin xyz="0 0 -0.015" rpy="1.5708 -0 0"/>
      <geometry>
        <mesh filename="package://my_robot_description/assets/llanta_dere_tra.stl"/>
      </geometry>
    </collision>
  </link>
  <!-- Joint from base_link to llanta_dere_tra -->
  <joint name="llanta_dere_tra_joint" type="continuous">
    <origin xyz="-0.0859 -0.095 0.0162" rpy="-1.5708 -0 0"/>
    <parent link="base_link"/>
    <child link="llanta_dere_tra_link"/>
    <axis xyz="0 0 1"/>
    <limit effort="100" velocity="100"/>
  </joint>
  <!-- Link llanta_iz_del -->
  <link name="llanta_iz_del_link">
    <inertial>
      <origin xyz="-0 0 -0.0264625" rpy="0 0 0"/>
      <mass value="0.324568"/>
      <inertia ixx="0.000101332" ixy="0" ixz="0" iyy="0.000102245" iyz="0" izz="0.000172547"/>
    </inertial>
    <!-- Part llanta_iz_del -->
    <visual>
      <origin xyz="-0 0 -0.04169" rpy="-1.5708 -0 0"/>
      <geometry>
        <mesh filename="package://my_robot_description/assets/llanta_iz_del.stl"/>
      </geometry>
      <material name="llanta_iz_del_material">
        <color rgba="0.980392 0.713725 0.00392157 1"/>
      </material>
    </visual>
    <collision>
      <origin xyz="-0 0 -0.04169" rpy="-1.5708 -0 0"/>
      <geometry>
        <mesh filename="package://my_robot_description/assets/llanta_iz_del.stl"/>
      </geometry>
    </collision>
  </link>
  <!-- Joint from base_link to llanta_iz_del -->
  <joint name="llanta_iz_del_joint" type="continuous">
    <origin xyz="0.0441 0.095 0.0162" rpy="1.5708 -0 0"/>
    <parent link="base_link"/>
    <child link="llanta_iz_del_link"/>
    <axis xyz="0 0 -1"/>
    <limit effort="100" velocity="100"/>
  </joint>
  <!-- Link llanta_iz_tra -->
  <link name="llanta_iz_tra_link">
    <inertial>
      <origin xyz="0 -0 -0.0264625" rpy="0 0 0"/>
      <mass value="0.324568"/>
      <inertia ixx="0.000101332" ixy="0" ixz="0" iyy="0.000102245" iyz="0" izz="0.000172547"/>
    </inertial>
    <!-- Part llanta_iz_tra -->
    <visual>
      <origin xyz="0 -0 -0.04169" rpy="-1.5708 -0 0"/>
      <geometry>
        <mesh filename="package://my_robot_description/assets/llanta_iz_tra.stl"/>
      </geometry>
      <material name="llanta_iz_tra_material">
        <color rgba="0.980392 0.713725 0.00392157 1"/>
      </material>
    </visual>
    <collision>
      <origin xyz="0 -0 -0.04169" rpy="-1.5708 -0 0"/>
      <geometry>
        <mesh filename="package://my_robot_description/assets/llanta_iz_tra.stl"/>
      </geometry>
    </collision>
  </link>
  <!-- Joint from base_link to llanta_iz_tra -->
  <joint name="llanta_iz_tra_joint" type="continuous">
    <origin xyz="-0.0859 0.095 0.0162" rpy="1.5708 -0 0"/>
    <parent link="base_link"/>
    <child link="llanta_iz_tra_link"/>
    <axis xyz="0 0 -1"/>
    <limit effort="100" velocity="100"/>
  </joint>

</robot>  